Workbook

Sheet How To Use
A1: Farm Economy Simulator
A2: Tests the money side of the Farming Horror Game design doc: crops, plots, labor, debt payments, medical bills and the corn quota.
A4: Color key
A5: Blue text on yellow = inputs you can change. Black = formulas. Green = values pulled from another sheet.
A7: Sheets
A8: Inputs - every number from the design doc (crop prices, debt, medical bill, scaling, trap ramp). Change these to tune the game.
A9: Season Plan - plan a 7-day season: how many plots of each crop to plant each day, corn held for the cart, deaths each night. The Status row flags any day that breaks a rule, and the summary at the top says whether the season is won.
A10: Crop Value - profit per plot per day for each crop, to compare crops at a glance.
A11: Player Scaling - what 2, 3 and 4 players can do against what they owe.
A13: Assumptions (the design doc doesn't pin these down)
A14: 1. 'Grows in 1 day' means plant today, harvest and sell tomorrow. Change Grows-in days on Inputs to test other readings.
A15: 2. Moonflowers are planted by day in the 4-plot bed, harvested that night and sold at dawn, so they count toward a payment due that dawn.
... A22: The Season Plan opens with the best-case turnip rush: all plots on turnips days 1-3, moonflowers from day 3, then 8 corn on day 4 for the cart. With 4 players and no deaths it misses the first payment, which is the problem this sheet was built to show. Set Players to 2 on Inputs to compare (then fix the 'Not enough hands' days).

Sheet Inputs
A1: Inputs
A2: Starting values from Farming_Horror_Game_Concept.md unless noted. Change the blue cells.
A3: Crops (coins per plot)
A4: Crop | B4: Grows in (days) | C4: Seed cost | D4: Sells for | E4: Unlocks on day | F4: Notes
A5: Turnips | B5: 1 | C5: 4 | D5: 10 | E5: 1 | F5: Short and safe. Low value, steady money.
A6: Pumpkins | B6: 2 | C6: 10 | D6: 25 | E6: 2 | F6: Low and sprawling.
A7: Corn | B7: 3 | C7: 15 | D7: 45 | E7: 1 | F7: Tall from day 2. Needed for the festival.
A8: Moonflowers | B8: 1 | C8: 25 | D8: 70 | E8: 3 | F8: Grows in 1 night; harvested that night in the 4-plot bed. Grows-in is not used.
A10: Farm and team
A11: Players on team (2-4) | B11: 4 | F11: Change this to test 2 or 3 players.
A12: Field plots | B12: 16 | F12: Starts at 16; upgrades add up to 24.
A13: Moonflower bed plots | B13: 4 | F13: Separate from the field plots.
A14: Plots one player tends per day | B14: 6 | F14: Doc: 'one player tends about 6 plots a day'.
A15: Labor per trap cleared (plot-equivalents) | B15: 0 | F15: Assumption. 0 = trap sweeps are already inside the 6-plot figure.
A17: Bank and festival
A18: Starting coins | B18: 60
A19: Total debt | B19: 1200
A20: First payment | B20: 400 | F20: Scaled by team size (see below).
A21: First payment due at dawn after night | B21: 3
A22: Final payment (debt minus first payment) | B22: =B19-B20 -> 800 | F22: Due at dawn after night 7 (the Harvest Moon).
A23: Festival pays per corn plot on the cart | B23: 45 | F23: Assumption: doc says the festival buys corn but gives no price. Set 0 if unpaid.
A24: Corn quota (plots on the cart) | B24: 8
A26: Medical bill
A27: Per death | B27: 50
A28: First death each night | B28: 25
A29: Cap per night | B29: 120
A30: Bill never takes the bank below | B30: 4 | F30: The price of a turnip seed pack.
A32: Team-size scaling (payments, traps, disturbances)
A33: Players | B33: Scale
A34: 2 | B34: 0.7
A35: 3 | B35: 0.85
A36: 4 | B36: 1
A37: Active scale for this team | B37: =IFERROR(INDEX(B34:B36,MATCH(B11,A34:A36,0)),1) -> 1 | F37: Looked up from Players on team.
A39: Ramp-up, 4 players (traps set each night are cleared the next day)
A40: Day | B40: Daytime disturbances | C40: Bear traps set that night | D40: Pits set that night
A41: 1 | B41: 1 | C41: 2 | D41: 1
A42: 2 | B42: 1 | C42: 2 | D42: 2
A43: 3 | B43: 2 | C43: 3 | D43: 2
A44: 4 | B44: 2 | C44: 3 | D44: 3
A45: 5 | B45: 3 | C45: 4 | D45: 3
...

Sheet Season Plan
B1: Season Plan
B2: Edit the blue cells in 'Your plan'. Everything else calculates. Coins throughout.
B4: Season summary
B5: Players on team | C5: =Inputs!$B$11 -> 4
B6: First payment (scaled for team size) | C6: =Inputs!$B$20*Inputs!$B$37 -> 400
B7: Final payment (scaled for team size) | C7: =Inputs!$B$22*Inputs!$B$37 -> 800
B8: First payment | C8: =IF(INDEX($C$38:$I$38,Inputs!$B$21)>=0,"Made, "&TEXT(INDEX($C$38:$I$38,Inputs!$B$21),"#,##0")&" left","MISSED by "&TEXT(-INDEX($C$38:$I$38,Inputs!$B$21),"#,##0")) -> MISSED by 38
B9: Final payment | C9: =IF(I38>=0,"Made, "&TEXT(I38,"#,##0")&" left","MISSED by "&TEXT(-I38,"#,##0")) -> Made, 426 left
B10: Corn quota | C10: =IF(SUM($C$21:$I$21)>=Inputs!$B$24,"Met ("&SUM($C$21:$I$21)&" plots)","Short by "&(Inputs!$B$24-SUM($C$21:$I$21))&" plots") -> Met (8 plots)
B11: Days with a problem | C11: =COUNTIF($C$46:$I$46,"<>OK") -> 2
B12: Season result | C12: =IF(AND(INDEX($C$38:$I$38,Inputs!$B$21)>=0,I38>=0,SUM($C$21:$I$21)>=Inputs!$B$24,COUNTIF($C$46:$I$46,"<>OK")=0),"WIN (if anyone survives the Harvest Moon)","LOSS") -> LOSS
B13: Moonflowers' share of all income | C13: =IFERROR(SUM($C$34:$I$34)/(SUM($C$29:$I$29)+SUM($C$34:$I$34)+SUM($C$36:$I$36)),0) -> 0.56680162
B15: Day | C15: 1 | D15: 2 | E15: 3 | F15: 4 | G15: 5 | H15: 6 | I15: 7
B16: Your plan (plots)
B17: Turnips planted | C17: 15 | D17: 16 | E17: 16 | F17: 8 | G17: 8 | H17: 8 | I17: 0
B18: Pumpkins planted | C18: 0 | D18: 0 | E18: 0 | F18: 0 | G18: 0 | H18: 0 | I18: 0
B19: Corn planted | C19: 0 | D19: 0 | E19: 0 | F19: 8 | G19: 0 | H19: 0 | I19: 0
B20: Moonflowers planted (bed) | C20: 0 | D20: 0 | E20: 4 | F20: 4 | G20: 4 | H20: 4 | I20: 4
B21: Corn held for the festival cart | C21: 0 | D21: 0 | E21: 0 | F21: 0 | G21: 0 | H21: 0 | I21: 8
B22: Deaths that night | C22: 0 | D22: 0 | E22: 0 | F22: 0 | G22: 0 | H22: 0 | I22: 0
B24: Daytime
B25: Cash at start of day | C25: =Inputs!$B$18 -> 60 | D25: =C38 -> 0 | E25: =D38 -> 86 | F25: =E38 -> -38 | G25: =F38 -> 150 | H25: =G38 -> 378 | I25: =H38 -> 606
B26: Turnips harvested | C26: =SUMPRODUCT($C$17:$I$17*(($C$15:$I$15+Inputs!$B$5)=C$15)) -> 0 | D26: =SUMPRODUCT($C$17:$I$17*(($C$15:$I$15+Inputs!$B$5)=D$15)) -> 15 | E26: =SUMPRODUCT($C$17:$I$17*(($C$15:$I$15+Inputs!$B$5)=E$15)) -> 16 | F26: =SUMPRODUCT($C$17:$I$17*(($C$15:$I$15+Inputs!$B$5)=F$15)) -> 16 | G26: =SUMPRODUCT($C$17:$I$17*(($C$15:$I$15+Inputs!$B$5)=G$15)) -> 8 | H26: =SUMPRODUCT($C$17:$I$17*(($C$15:$I$15+Inputs!$B$5)=H$15)) -> 8 | I26: =SUMPRODUCT($C$17:$I$17*(($C$15:$I$15+Inputs!$B$5)=I$15)) -> 8
B27: Pumpkins harvested | C27: =SUMPRODUCT($C$18:$I$18*(($C$15:$I$15+Inputs!$B$6)=C$15)) -> 0 | D27: =SUMPRODUCT($C$18:$I$18*(($C$15:$I$15+Inputs!$B$6)=D$15)) -> 0 | E27: =SUMPRODUCT($C$18:$I$18*(($C$15:$I$15+Inputs!$B$6)=E$15)) -> 0 | F27: =SUMPRODUCT($C$18:$I$18*(($C$15:$I$15+Inputs!$B$6)=F$15)) -> 0 | G27: =SUMPRODUCT($C$18:$I$18*(($C$15:$I$15+Inputs!$B$6)=G$15)) -> 0 | H27: =SUMPRODUCT($C$18:$I$18*(($C$15:$I$15+Inputs!$B$6)=H$15)) -> 0 | I27: =SUMPRODUCT($C$18:$I$18*(($C$15:$I$15+Inputs!$B$6)=I$15)) -> 0
B28: Corn harvested | C28: =SUMPRODUCT($C$19:$I$19*(($C$15:$I$15+Inputs!$B$7)=C$15)) -> 0 | D28: =SUMPRODUCT($C$19:$I$19*(($C$15:$I$15+Inputs!$B$7)=D$15)) -> 0 | E28: =SUMPRODUCT($C$19:$I$19*(($C$15:$I$15+Inputs!$B$7)=E$15)) -> 0 | F28: =SUMPRODUCT($C$19:$I$19*(($C$15:$I$15+Inputs!$B$7)=F$15)) -> 0 | G28: =SUMPRODUCT($C$19:$I$19*(($C$15:$I$15+Inputs!$B$7)=G$15)) -> 0 | H28: =SUMPRODUCT($C$19:$I$19*(($C$15:$I$15+Inputs!$B$7)=H$15)) -> 0 | I28: =SUMPRODUCT($C$19:$I$19*(($C$15:$I$15+Inputs!$B$7)=I$15)) -> 8
B29: Stand sales | C29: =C26*Inputs!$D$5+C27*Inputs!$D$6+(C28-C21)*Inputs!$D$7 -> 0 | D29: =D26*Inputs!$D$5+D27*Inputs!$D$6+(D28-D21)*Inputs!$D$7 -> 150 | E29: =E26*Inputs!$D$5+E27*Inputs!$D$6+(E28-E21)*Inputs!$D$7 -> 160 | F29: =F26*Inputs!$D$5+F27*Inputs!$D$6+(F28-F21)*Inputs!$D$7 -> 160 | G29: =G26*Inputs!$D$5+G27*Inputs!$D$6+(G28-G21)*Inputs!$D$7 -> 80 | H29: =H26*Inputs!$D$5+H27*Inputs!$D$6+(H28-H21)*Inputs!$D$7 -> 80 | I29: =I26*Inputs!$D$5+I27*Inputs!$D$6+(I28-I21)*Inputs!$D$7 -> 80
B30: Seed costs | C30: =C17*Inputs!$C$5+C18*Inputs!$C$6+C19*Inputs!$C$7+C20*Inputs!$C$8 -> 60 | D30: =D17*Inputs!$C$5+D18*Inputs!$C$6+D19*Inputs!$C$7+D20*Inputs!$C$8 -> 64 | E30: =E17*Inputs!$C$5+E18*Inputs!$C$6+E19*Inputs!$C$7+E20*Inputs!$C$8 -> 164 | F30: =F17*Inputs!$C$5+F18*Inputs!$C$6+F19*Inputs!$C$7+F20*Inputs!$C$8 -> 252 | G30: =G17*Inputs!$C$5+G18*Inputs!$C$6+G19*Inputs!$C$7+G20*Inputs!$C$8 -> 132 | H30: =H17*Inputs!$C$5+H18*Inputs!$C$6+H19*Inputs!$C$7+H20*Inputs!$C$8 -> 132 | I30: =I17*Inputs!$C$5+I18*Inputs!$C$6+I19*Inputs!$C$7+I20*Inputs!$C$8 -> 100
B31: Cash after the day | C31: =C25+C29-C30 -> 0 | D31: =D25+D29-D30 -> 86 | E31: =E25+E29-E30 -> 82 | F31: =F25+F29-F30 -> -130 | G31: =G25+G29-G30 -> 98 | H31: =H25+H29-H30 -> 326 | I31: =I25+I29-I30 -> 586
B33: Night and dawn
B34: Moonflower sales at dawn | C34: =C20*Inputs!$D$8 -> 0 | D34: =D20*Inputs!$D$8 -> 0 | E34: =E20*Inputs!$D$8 -> 280 | F34: =F20*Inputs!$D$8 -> 280 | G34: =G20*Inputs!$D$8 -> 280 | H34: =H20*Inputs!$D$8 -> 280 | I34: =I20*Inputs!$D$8 -> 280
B35: Medical bill | C35: =IF(C22<=0,0,MIN(MIN(Inputs!$B$29,Inputs!$B$28+(C22-1)*Inputs!$B$27),MAX(0,C31+C34-Inputs!$B$30))) -> 0 | D35: =IF(D22<=0,0,MIN(MIN(Inputs!$B$29,Inputs!$B$28+(D22-1)*Inputs!$B$27),MAX(0,D31+D34-Inputs!$B$30))) -> 0 | E35: =IF(E22<=0,0,MIN(MIN(Inputs!$B$29,Inputs!$B$28+(E22-1)*Inputs!$B$27),MAX(0,E31+E34-Inputs!$B$30))) -> 0 | F35: =IF(F22<=0,0,MIN(MIN(Inputs!$B$29,Inputs!$B$28+(F22-1)*Inputs!$B$27),MAX(0,F31+F34-Inputs!$B$30))) -> 0 | G35: =IF(G22<=0,0,MIN(MIN(Inputs!$B$29,Inputs!$B$28+(G22-1)*Inputs!$B$27),MAX(0,G31+G34-Inputs!$B$30))) -> 0 | H35: =IF(H22<=0,0,MIN(MIN(Inputs!$B$29,Inputs!$B$28+(H22-1)*Inputs!$B$27),MAX(0,H31+H34-Inputs!$B$30))) -> 0 | I35: =IF(I22<=0,0,MIN(MIN(Inputs!$B$29,Inputs!$B$28+(I22-1)*Inputs!$B$27),MAX(0,I31+I34-Inputs!$B$30))) -> 0
B36: Festival cart payout | C36: =IF(C$15=7,SUM($C$21:$I$21)*Inputs!$B$23,0) -> 0 | D36: =IF(D$15=7,SUM($C$21:$I$21)*Inputs!$B$23,0) -> 0 | E36: =IF(E$15=7,SUM($C$21:$I$21)*Inputs!$B$23,0) -> 0 | F36: =IF(F$15=7,SUM($C$21:$I$21)*Inputs!$B$23,0) -> 0 | G36: =IF(G$15=7,SUM($C$21:$I$21)*Inputs!$B$23,0) -> 0 | H36: =IF(H$15=7,SUM($C$21:$I$21)*Inputs!$B$23,0) -> 0 | I36: =IF(I$15=7,SUM($C$21:$I$21)*Inputs!$B$23,0) -> 360
B37: Bank payment due | C37: =IF(C$15=Inputs!$B$21,Inputs!$B$20*Inputs!$B$37,IF(C$15=7,Inputs!$B$22*Inputs!$B$37,0)) -> 0 | D37: =IF(D$15=Inputs!$B$21,Inputs!$B$20*Inputs!$B$37,IF(D$15=7,Inputs!$B$22*Inputs!$B$37,0)) -> 0 | E37: =IF(E$15=Inputs!$B$21,Inputs!$B$20*Inputs!$B$37,IF(E$15=7,Inputs!$B$22*Inputs!$B$37,0)) -> 400 | F37: =IF(F$15=Inputs!$B$21,Inputs!$B$20*Inputs!$B$37,IF(F$15=7,Inputs!$B$22*Inputs!$B$37,0)) -> 0 | G37: =IF(G$15=Inputs!$B$21,Inputs!$B$20*Inputs!$B$37,IF(G$15=7,Inputs!$B$22*Inputs!$B$37,0)) -> 0 | H37: =IF(H$15=Inputs!$B$21,Inputs!$B$20*Inputs!$B$37,IF(H$15=7,Inputs!$B$22*Inputs!$B$37,0)) -> 0 | I37: =IF(I$15=Inputs!$B$21,Inputs!$B$20*Inputs!$B$37,IF(I$15=7,Inputs!$B$22*Inputs!$B$37,0)) -> 800
B38: Cash at dawn | C38: =C31+C34-C35+C36-C37 -> 0 | D38: =D31+D34-D35+D36-D37 -> 86 | E38: =E31+E34-E35+E36-E37 -> -38 | F38: =F31+F34-F35+F36-F37 -> 150 | G38: =G31+G34-G35+G36-G37 -> 378 | H38: =H31+H34-H35+H36-H37 -> 606 | I38: =I31+I34-I35+I36-I37 -> 426
B40: Checks
B41: Field plots in use | C41: =SUMPRODUCT($C$17:$I$17*($C$15:$I$15<=C$15)*(($C$15:$I$15+Inputs!$B$5)>C$15))+SUMPRODUCT($C$18:$I$18*($C$15:$I$15<=C$15)*(($C$15:$I$15+Inputs!$B$6)>C$15))+SUMPRODUCT($C$19:$I$19*($C$15:$I$15<=C$15)*(($C$15:$I$15+Inputs!$B$7)>C$15)) -> 15 | D41: =SUMPRODUCT($C$17:$I$17*($C$15:$I$15<=D$15)*(($C$15:$I$15+Inputs!$B$5)>D$15))+SUMPRODUCT($C$18:$I$18*($C$15:$I$15<=D$15)*(($C$15:$I$15+Inputs!$B$6)>D$15))+SUMPRODUCT($C$19:$I$19*($C$15:$I$15<=D$15)*(($C$15:$I$15+Inputs!$B$7)>D$15)) -> 16 | E41: =SUMPRODUCT($C$17:$I$17*($C$15:$I$15<=E$15)*(($C$15:$I$15+Inputs!$B$5)>E$15))+SUMPRODUCT($C$18:$I$18*($C$15:$I$15<=E$15)*(($C$15:$I$15+Inputs!$B$6)>E$15))+SUMPRODUCT($C$19:$I$19*($C$15:$I$15<=E$15)*(($C$15:$I$15+Inputs!$B$7)>E$15)) -> 16 | F41: =SUMPRODUCT($C$17:$I$17*($C$15:$I$15<=F$15)*(($C$15:$I$15+Inputs!$B$5)>F$15))+SUMPRODUCT($C$18:$I$18*($C$15:$I$15<=F$15)*(($C$15:$I$15+Inputs!$B$6)>F$15))+SUMPRODUCT($C$19:$I$19*($C$15:$I$15<=F$15)*(($C$15:$I$15+Inputs!$B$7)>F$15)) -> 16 | G41: =SUMPRODUCT($C$17:$I$17*($C$15:$I$15<=G$15)*(($C$15:$I$15+Inputs!$B$5)>G$15))+SUMPRODUCT($C$18:$I$18*($C$15:$I$15<=G$15)*(($C$15:$I$15+Inputs!$B$6)>G$15))+SUMPRODUCT($C$19:$I$19*($C$15:$I$15<=G$15)*(($C$15:$I$15+Inputs!$B$7)>G$15)) -> 16 | H41: =SUMPRODUCT($C$17:$I$17*($C$15:$I$15<=H$15)*(($C$15:$I$15+Inputs!$B$5)>H$15))+SUMPRODUCT($C$18:$I$18*($C$15:$I$15<=H$15)*(($C$15:$I$15+Inputs!$B$6)>H$15))+SUMPRODUCT($C$19:$I$19*($C$15:$I$15<=H$15)*(($C$15:$I$15+Inputs!$B$7)>H$15)) -> 16 | I41: =SUMPRODUCT($C$17:$I$17*($C$15:$I$15<=I$15)*(($C$15:$I$15+Inputs!$B$5)>I$15))+SUMPRODUCT($C$18:$I$18*($C$15:$I$15<=I$15)*(($C$15:$I$15+Inputs!$B$6)>I$15))+SUMPRODUCT($C$19:$I$19*($C$15:$I$15<=I$15)*(($C$15:$I$15+Inputs!$B$7)>I$15)) -> 0
B42: Field plots available | C42: =Inputs!$B$12 -> 16 | D42: =Inputs!$B$12 -> 16 | E42: =Inputs!$B$12 -> 16 | F42: =Inputs!$B$12 -> 16 | G42: =Inputs!$B$12 -> 16 | H42: =Inputs!$B$12 -> 16 | I42: =Inputs!$B$12 -> 16
B43: Traps to clear today | C43: =0 -> 0 | D43: =ROUND((INDEX(Inputs!$C$41:$C$47,D$15-1)+INDEX(Inputs!$D$41:$D$47,D$15-1))*Inputs!$B$37,0) -> 3 | E43: =ROUND((INDEX(Inputs!$C$41:$C$47,E$15-1)+INDEX(Inputs!$D$41:$D$47,E$15-1))*Inputs!$B$37,0) -> 4 | F43: =ROUND((INDEX(Inputs!$C$41:$C$47,F$15-1)+INDEX(Inputs!$D$41:$D$47,F$15-1))*Inputs!$B$37,0) -> 5 | G43: =ROUND((INDEX(Inputs!$C$41:$C$47,G$15-1)+INDEX(Inputs!$D$41:$D$47,G$15-1))*Inputs!$B$37,0) -> 6 | H43: =ROUND((INDEX(Inputs!$C$41:$C$47,H$15-1)+INDEX(Inputs!$D$41:$D$47,H$15-1))*Inputs!$B$37,0) -> 7 | I43: =ROUND((INDEX(Inputs!$C$41:$C$47,I$15-1)+INDEX(Inputs!$D$41:$D$47,I$15-1))*Inputs!$B$37,0) -> 9
B44: Labor needed (plot-equivalents) | C44: =C41+C20+C43*Inputs!$B$15 -> 15 | D44: =D41+D20+D43*Inputs!$B$15 -> 16 | E44: =E41+E20+E43*Inputs!$B$15 -> 20 | F44: =F41+F20+F43*Inputs!$B$15 -> 20 | G44: =G41+G20+G43*Inputs!$B$15 -> 20 | H44: =H41+H20+H43*Inputs!$B$15 -> 20 | I44: =I41+I20+I43*Inputs!$B$15 -> 4
B45: Labor available | C45: =Inputs!$B$11*Inputs!$B$14 -> 24 | D45: =Inputs!$B$11*Inputs!$B$14 -> 24 | E45: =Inputs!$B$11*Inputs!$B$14 -> 24 | F45: =Inputs!$B$11*Inputs!$B$14 -> 24 | G45: =Inputs!$B$11*Inputs!$B$14 -> 24 | H45: =Inputs!$B$11*Inputs!$B$14 -> 24 | I45: =Inputs!$B$11*Inputs!$B$14 -> 24
...

Sheet Crop Value
A1: Crop Value
A2: Which crop earns the most from one plot. All values pull from Inputs.
A4: Crop | B4: Grows in (days) | C4: Profit per harvest | D4: Return on seed | E4: Profit per plot per day | F4: Rank | G4: Note
A5: =Inputs!A5 -> Turnips | B5: =Inputs!B5 -> 1 | C5: =Inputs!D5-Inputs!C5 -> 6 | D5: =IFERROR(C5/Inputs!C5,0) -> 1.5 | E5: =IFERROR(C5/MAX(1,B5),0) -> 6 | F5: =RANK(E5,$E$5:$E$8) -> 4
A6: =Inputs!A6 -> Pumpkins | B6: =Inputs!B6 -> 2 | C6: =Inputs!D6-Inputs!C6 -> 15 | D6: =IFERROR(C6/Inputs!C6,0) -> 1.5 | E6: =IFERROR(C6/MAX(1,B6),0) -> 7.5 | F6: =RANK(E6,$E$5:$E$8) -> 3
A7: =Inputs!A7 -> Corn | B7: =Inputs!B7 -> 3 | C7: =Inputs!D7-Inputs!C7 -> 30 | D7: =IFERROR(C7/Inputs!C7,0) -> 2 | E7: =IFERROR(C7/MAX(1,B7),0) -> 10 | F7: =RANK(E7,$E$5:$E$8) -> 2 | G7: Ties up a plot 3 days and costs the most cash up front.
A8: =Inputs!A8 -> Moonflowers | B8: =Inputs!B8 -> 1 | C8: =Inputs!D8-Inputs!C8 -> 45 | D8: =IFERROR(C8/Inputs!C8,0) -> 1.8 | E8: =IFERROR(C8/MAX(1,B8),0) -> 45 | F8: =RANK(E8,$E$5:$E$8) -> 1 | G8: Only 4 plots, but every night from day 3. Counted per night.

Sheet Player Scaling
A1: Player Scaling
A2: What each team size can do against what it owes. Pulls from Inputs.
B4: 2 players | C4: 3 players | D4: 4 players | E4: Note
A5: Scale | B5: =Inputs!B34 -> 0.7 | C5: =Inputs!B35 -> 0.85 | D5: =Inputs!B36 -> 1 | E5: Payments and traps scale; plots and moonflowers don't.
A6: Labor available per day | B6: =Inputs!A34*Inputs!$B$14 -> 12 | C6: =Inputs!A35*Inputs!$B$14 -> 18 | D6: =Inputs!A36*Inputs!$B$14 -> 24
A7: Field plots the team can tend (after the moonflower bed) | B7: =MIN(Inputs!$B$12,MAX(0,B6-Inputs!$B$13)) -> 8 | C7: =MIN(Inputs!$B$12,MAX(0,C6-Inputs!$B$13)) -> 14 | D7: =MIN(Inputs!$B$12,MAX(0,D6-Inputs!$B$13)) -> 16 | E7: Labor minus 4 for the bed, capped at field plots.
A8: Turnip profit per day from those plots | B8: =B7*(Inputs!$D$5-Inputs!$C$5)/Inputs!$B$5 -> 48 | C8: =C7*(Inputs!$D$5-Inputs!$C$5)/Inputs!$B$5 -> 84 | D8: =D7*(Inputs!$D$5-Inputs!$C$5)/Inputs!$B$5 -> 96
A9: Moonflower profit per night | B9: =Inputs!$B$13*(Inputs!$D$8-Inputs!$C$8) -> 180 | C9: =Inputs!$B$13*(Inputs!$D$8-Inputs!$C$8) -> 180 | D9: =Inputs!$B$13*(Inputs!$D$8-Inputs!$C$8) -> 180 | E9: Same for every team size.
A10: First payment | B10: =Inputs!$B$20*B5 -> 280 | C10: =Inputs!$B$20*C5 -> 340 | D10: =Inputs!$B$20*D5 -> 400
A11: Final payment | B11: =Inputs!$B$22*B5 -> 560 | C11: =Inputs!$B$22*C5 -> 680 | D11: =Inputs!$B$22*D5 -> 800
A12: Total owed | B12: =B10+B11 -> 840 | C12: =C10+C11 -> 1020 | D12: =D10+D11 -> 1200
A13: Moonflower nights in a season | B13: =MAX(0,7-Inputs!$E$8+1) -> 5 | C13: =MAX(0,7-Inputs!$E$8+1) -> 5 | D13: =MAX(0,7-Inputs!$E$8+1) -> 5 | E13: Every night from the unlock day to night 7.
A14: Share of total debt moonflowers can cover | B14: =IFERROR(B9*B13/B12,0) -> 1.0714286 | C14: =IFERROR(C9*C13/C12,0) -> 0.88235294 | D14: =IFERROR(D9*D13/D12,0) -> 0.75 | E14: Above 100% means the day crops barely matter.
